Workbook

Sheet Cópia de Extração
A1: LLM1: CHATGPT
A2: LLM2: GEMINI
A3: ID do artigo | B3: Tipo de publicação | C3: Local de publicação | D3: Título | E3: Link | F3: Ano | G3: Autores | H3: País | I3: Base de Dados | J3: RQ (Pergunta de Pesquisa) | K3: Extração LLM 1 (ChatGPT) | L3: Extração LLM 2 (Gemini) | M3: Extração validada (humana) | N3: ChatGPT acertou? | O3: Gemini acertou? | P3: Concordância entre LLMs | Q3: Observações / Comentários
A4: ES01 | B4: Journal | C4: Biological Psychology | D4: Effects of working memory training on EEG, cognitive performance, and self-report indices potentially relevant for social anxiety | E4: PubMed | F4: 2020 | G4: Xin Zhao, Chen Dang, Joseph H R Maes | I4: PubMed | J4: RQ1 | K4: <<Texto extraído da IA>> | L4: <<Texto extraído da IA>> | P4: =IF(OR(N4="",O4=""),"",IF(N4=O4,"Igual","Diferente"))
A5: ES02 | B5: Journal | C5: international psychogeriatrics | D5: Effects of repetitive paired associative stimulation on brain plasticity and working memory in Alzheimer's disease: a pilot randomized double-blind-controlled trial | E5: PubMed | F5: 2020 | G5: Sanjeev Kumar, Reza Zomorrodi, Zaid Ghazala, Michelle S Goodman, Daniel M Blumberger, Zafiris J Daskalakis, Corinne E Fischer, Benoit H Mulsant, Bruce G Pollock, Tarek K Rajji | I5: PubMed | J5: RQ2 | P5: =IF(OR(N5="",O5=""),"",IF(N5=O5,"Igual","Diferente"))
A6: ES03 | B6: Journal | C6: Schizophrenia Research: Cognition | D6: The aperiodic and periodic activities of EEG dynamically relate with cognitive performance in schizophrenia | E6: PubMed | F6: 2025 | G6: Kexin Zhang, Yunfei Ji, Xiaodong Guo, Tianqi Gao, Xuemin Zhang, Xin Yu, Jing Wang | I6: PubMed | J6: RQ3 | P6: =IF(OR(N6="",O6=""),"",IF(N6=O6,"Igual","Diferente"))
A7: ES04 | D7: Psilocybin-assisted neurofeedback for the improvement of executive functions: a randomized... feasibility study | E7: 10.1098/rstb.2023.0095 | F7: 2024 | G7: Enriquez-Geppert S, et al. | I7: PubMed | J7: RQ4 | P7: =IF(OR(N7="",O7=""),"",IF(N7=O7,"Igual","Diferente"))
A8: ES05 | B8: Journal | C8: Sensors (Basel) | D8: Investigating the Impact of Guided Imagery on Stress, Brain Functions, and Attention: A Randomized Trial | E8: 10.3390/s23136210 | F8: 2023 | G8: Zemla K, et al. | I8: PubMed | J8: RQ5 | P8: =IF(OR(N8="",O8=""),"",IF(N8=O8,"Igual","Diferente"))
A9: ES06 | B9: Journal | C9: Journal of Affective Disorders | D9: Subanesthetic ketamine alters EEG signal complexity: Implications for treatment stratification in depression | E9: 10.1016/j.jad.2025.119477 | F9: 2025 | G9: Chan WL, et al. | I9: PubMed | J9: RQ6 | P9: =IF(OR(N9="",O9=""),"",IF(N9=O9,"Igual","Diferente"))
A10: ES07 | B10: Journal | C10: JMIR Ment Health | D10: Design and Implementation of a Brief Digital Mindfulness and Compassion Training App...: Cluster Randomized Controlled Trial | E10: 10.2196/49467 | F10: 2024 | G10: Jaiswal S, et al. | I10: PubMed | J10: RQ7 | P10: =IF(OR(N10="",O10=""),"",IF(N10=O10,"Igual","Diferente"))
A11: ES08 | B11: Journal | C11: Scientific Reports | D11: Feasibility of a novel neurofeedback system: a parallel randomized single-blinded pilot study | E11: 10.1038/s41598-023-44545-1 | F11: 2023 | G11: Horváth D, et al. | I11: PubMed | J11: RQ8 | P11: =IF(OR(N11="",O11=""),"",IF(N11=O11,"Igual","Diferente"))
A12: ES09 | B12: Journal | C12: Human Psychopharmacol | D12: Comprehensive Mitigation of Peripheral and Central Stress Responses by Nx4: Insights From EEG and Heart Rate Variability... | E12: 10.1002/hup.70020 | F12: 2025 | G12: Krylova M, et al. | I12: PubMed | J12: RQ9 | P12: =IF(OR(N12="",O12=""),"",IF(N12=O12,"Igual","Diferente"))
A13: ES10 | B13: Journal | C13: Biological Psychology | D13: Effects of working memory training on EEG, cognitive performance, and self-report indices potentially relevant for social anxiety | E13: https://doi.org/10.1016/j.biopsycho.2019.107840 | F13: 2020 | G13: Zhao, Xin; Dang, Chen; Maes, Joseph H.R. | I13: Science Direct | P13: =IF(OR(N13="",O13=""),"",IF(N13=O13,"Igual","Diferente"))
A14: ES11 | B14: Journal | C14: Neuroscience Letters | D14: Investigation of the effects of transcranial direct current stimulation and neurofeedback by continuous performance test | E14: https://doi.org/10.1016/j.neulet.2019.134648 | F14: 2020 | G14: Guleken, Zozan; Eskikurt, Gökçer; Karamürsel, Sacit | I14: Science Direct | P14: =IF(OR(N14="",O14=""),"",IF(N14=O14,"Igual","Diferente"))
A15: ES12 | B15: Journal | C15: NeuroImage: Clinical | D15: Real-time fMRI neurofeedback amygdala training may influence kynurenine pathway metabolism in major depressive disorder | E15: https://doi.org/10.1016/j.nicl.2021.102559 | F15: 2021 | G15: Tsuchiyagaito, Aki; Smith, Jared L.; El-Sabbagh, Nour; Zotev, Vadim; Misaki, Masaya; Al Zoubi, Obada; Kent Teague, T.; Paulus, Martin P.; Bodurka, Jerzy; Savitz, Jonathan | I15: Science Direct | P15: =IF(OR(N15="",O15=""),"",IF(N15=O15,"Igual","Diferente"))
A16: ES13 | B16: Journal | C16: JMIR Ment Health | D16: Design and Implementation of a Brief Digital Mindfulness and Compassion Training App for Health Care Professionals: Cluster Randomized Controlled Trial | E16: https://doi.org/10.2196/49467 | F16: 2024 | G16: Jaiswal, Satish; Purpura, Suzanna R; Manchanda, James K; Nan, Jason; Azeez, Nihal; Ramanathan, Dhakshin; Mishra, Jyoti | I16: Science Direct | P16: =IF(OR(N16="",O16=""),"",IF(N16=O16,"Igual","Diferente"))
A17: ES14 | B17: Journal | C17: Brain Simulation | D17: Daily prefrontal closed-loop repetitive transcranial magnetic stimulation (rTMS) produces progressive EEG quasi-alpha phase entrainment in depressed adults | E17: https://doi.org/10.1016/j.brs.2022.02.008 | F17: 2022 | G17: Faller, Josef; Doose, Jayce; Sun, Xiaoxiao; Mclntosh, James R.; Saber, Golbarg T.; Lin, Yida; Teves, Joshua B.; Blankenship, Aidan; Huffman, Sarah; Goldman, Robin I.; George, Mark S.; Brown, Truman R.; Sajda, Paul | I17: Science Direct | P17: =IF(OR(N17="",O17=""),"",IF(N17=O17,"Igual","Diferente"))
A18: ES15 | D18: Preliminary Real-World Evidence Supporting the Efficacy of a Remote Neurofeedback System in Improving Mental Health: Retrospective Single-Group Pretest-Posttest Study | E18: https://doi.org/10.2196/35636 | F18: 2022 | G18: Whitehead, Jocelyne C; Neeman, Ron; Doniger, Glen M | I18: Science Direct | P18: =IF(OR(N18="",O18=""),"",IF(N18=O18,"Igual","Diferente"))
A19: ES16 | D19: Advancing Posttraumatic Stress Disorder Diagnosis and the Treatment of Trauma in Humanitarian Emergencies via Mobile Health: Protocol for a Proof-of-Concept Nonrandomized Controlled Trial | E19: https://doi.org/10.2196/38223 | F19: 2022 | G19: Pinto, Janaina V; Hunt, Caroline; O'Toole, Brian | I19: Science Direct | P19: =IF(OR(N19="",O19=""),"",IF(N19=O19,"Igual","Diferente"))
A20: ES17 | D20: Neuromodulation-Assisted Psychotherapy: Can Transcranial Magnetic Stimulation Increase The Efficacy Of Acceptance And Commitment Therapy For Comorbid Chronic Pain And Depression? | E20: https://doi.org/10.1016/j.jpain.2023.02.188 | F20: 2023 | G20: Tynan, Mara; Martinez, Erica; Chu, Gage; Ramanathan, Dhakshin; Herbert, Matthew S. | I20: Science Direct | P20: =IF(OR(N20="",O20=""),"",IF(N20=O20,"Igual","Diferente"))
A21: ES18 | D21: Individualized Spectral Features in First-Episode and Drug-Naïve Major Depressive Disorder: Insights From Periodic and Aperiodic Electroencephalography Analysis | E21: https://doi.org/10.1016/j.bpsc.2024.12.014 | F21: 2025 | G21: Li, Jiaxin; Xiong, Dongsheng; Gao, Chenyang; Huang, Yuanyuan; Li, Zhaobo; Zhou, Jing; Ning, Yuping; Wu, Fengchun; Wu, Kai | I21: Science Direct | P21: =IF(OR(N21="",O21=""),"",IF(N21=O21,"Igual","Diferente"))
A22: ES19 | D22: Effects of high carbon dioxide concentration on emotional processing: Based on multimodal evidence | E22: https://doi.org/10.1016/j.buildenv.2024.111434 | F22: 2024 | G22: Yang, Li; Zhang, Jiaxing; Yang, Yukai; Wang, Nan; Zhang, Zhen; Chen, Liqun | I22: Science Direct | P22: =IF(OR(N22="",O22=""),"",IF(N22=O22,"Igual","Diferente"))
A23: ES20 | D23: Rationale and study design of a trial to assess rTMS add-on value for the amelioration of negative symptoms of schizophrenia (RADOVAN) | E23: https://doi.org/10.1016/j.conctc.2022.100891 | F23: 2022 | G23: Hebel, T.; Langguth, B.; Schecklmann, M.; Schoisswohl, S.; Staudinger, S.; Schiller, A.; Ustohal, L.; Sverak, T.; Horky, M.; Kasparek, T.; Skront, T.; Hyza, M.; Poeppl, T.B.; Riester, M.L.; Schwemmer, L.; Zimmermann, S.; Sakreida, K. | I23: Science Direct | P23: =IF(OR(N23="",O23=""),"",IF(N23=O23,"Igual","Diferente"))
A24: ES21 | D24: Combined EEG-tDCS approach in resting state to reduce comorbid anxiety and depressive symptoms in affective disorders: A sham-controlled pilot study | E24: https://doi.org/10.1016/j.ibneur.2024.04.007 | F24: 2024 | G24: Couto, Tania A.; Gao, Fei; Lak, Davis C.; Yuan, Zhen | I24: Science Direct | P24: =IF(OR(N24="",O24=""),"",IF(N24=O24,"Igual","Diferente"))
A25: ES22 | D25: Binaural sound therapy for tinnitus treatment: A psychometric and neurophysiological evaluation | E25: https://doi.org/10.1016/j.amjoto.2021.103248 | F25: 2022 | G25: Ibarra-Zarate, David I.; Naal-Ruiz, Norberto E.; Alonso-Valerdi, Luz María | I25: Science Direct | P25: =IF(OR(N25="",O25=""),"",IF(N25=O25,"Igual","Diferente"))
A26: ES23 | D26: EEG Based Evaluation of Examination Stress and Test Anxiety Among College Students | E26: https://doi.org/10.1016/j.irbm.2021.06.011 | F26: 2022 | G26: Rajendran, V.G.; Jayalalitha, S.; Adalarasu, K. | I26: Science Direct | P26: =IF(OR(N26="",O26=""),"",IF(N26=O26,"Igual","Diferente"))
A27: ES24 | D27: A qualitative analysis of participant experience during an EEG-linked auditory targeted cognitive training exercise: Implications for implementation and protocol optimization | E27: https://doi.org/10.1016/j.psychres.2024.116254 | F27: 2024 | G27: Conroy, Carmen; Li, Francesca; Sprock, Joyce; Rabin, Borsika A.; Joshi, Yash B. | I27: Science Direct | P27: =IF(OR(N27="",O27=""),"",IF(N27=O27,"Igual","Diferente"))
A28: ES25 | D28: Chapter Five - The complex associations between adiposity, fitness, mental wellbeing and neurocognitive function after exercise: A randomized crossover trial in preadolescent children | E28: https://doi.org/10.1016/bs.pbr.2023.11.004 | F28: 2024 | G28: Logan, Nicole E.; Occidental, Nicole; Watrous, Jennifer N.H.; Lloyd, Katherine M.; Raine, Lauren B.; Kramer, Arthur F.; Hillman, Charles H. | I28: Science Direct | P28: =IF(OR(N28="",O28=""),"",IF(N28=O28,"Igual","Diferente"))
A29: ES26 | D29: Subanesthetic ketamine alters EEG signal complexity: Implications for treatment stratification in depression | E29: https://doi.org/10.1016/j.jad.2025.119477 | F29: 2025 | G29: Chan, Weng-Lam; Olbrich, Sebastian; Jiang, Xinwen; Zhang, Haoyun; Ip, Cheng-Teng; Brunovsky, Martin | I29: Science Direct | P29: =IF(OR(N29="",O29=""),"",IF(N29=O29,"Igual","Diferente"))
A30: ES27 | D30: BCI Facilitates the Improvement of Cognitive Functions in Children and Elderly | E30: https://ieeexplore.ieee.org/document/9061625 | F30: 2020 | G30: Cuntai Guan; Choon Guan Lim; Daniel Fung; Helen Juan Zhou; Ranga Krishnan; Tih Shih Lee | I30: IEEE Explore | P30: =IF(OR(N30="",O30=""),"",IF(N30=O30,"Igual","Diferente"))
A31: ES28 | D31: Closed-Loop Individual Music Neurofeedback Based on Brain-Computer Interaction for Student Stress Intervention | E31: https://ieeexplore.ieee.org/document/10973423 | F31: 2024 | G31: Mengxuan Hu; Jingxi Zhang; Guangying Pei; Tianyi Yan | I31: IEEE Explore | P31: =IF(OR(N31="",O31=""),"",IF(N31=O31,"Igual","Diferente"))
A32: ES29 | D32: The Role of Non-Invasive Neural Devices in Modern Neurorehabilitation and Mental Health Treatment | E32: https://ieeexplore.ieee.org/document/11013597 | F32: 2025 | G32: Adesh Pawar; Palash Gourshettiwar; Pradnyawant M. Gote; Vishal Kumar Choudhary; Prajyot Yesankar; Shrikant Khadse | I32: IEEE Explore | P32: =IF(OR(N32="",O32=""),"",IF(N32=O32,"Igual","Diferente"))
A33: ES30 | D33: Automated Generated Binaural Beats Using EEG: A User-Friendly Auditory Brain-Computer Interface | E33: https://ieeexplore.ieee.org/stamp/stamp.jsp?arnumber=9645921 | F33: 2021 | G33: S. Negi; R. Jain; S. Saboo; S. Kwatra | I33: IEEE Explore | P33: =IF(OR(N33="",O33=""),"",IF(N33=O33,"Igual","Diferente"))
A34: ES31 | D34: EEG-Driven Massage Headband For Anxiety Alleviation | E34: https://ieeexplore.ieee.org/stamp/stamp.jsp?arnumber=11013104 | F34: 2025 | G34: K. Sravani; S. Nadipineni; B. Anjali; C. Vedavathi; B. Ramya | I34: IEEE Explore | P34: =IF(OR(N34="",O34=""),"",IF(N34=O34,"Igual","Diferente"))
A35: ES32 | D35: Using Generative AI for Neurofeedback Content Personalization | E35: https://ieeexplore.ieee.org/stamp/stamp.jsp?arnumber=11036309 | F35: 2025 | G35: T. L. Shuler; D. A. Ostrowski | I35: IEEE Explore | P35: =IF(OR(N35="",O35=""),"",IF(N35=O35,"Igual","Diferente"))
A36: ES33 | D36: Closed-Loop Individual Music Neurofeedback Based on Brain-Computer Interaction for Student Stress Intervention | E36: https://ieeexplore.ieee.org/stamp/stamp.jsp?arnumber=10973423 | F36: 2024 | G36: M. Hu; J. Zhang; G. Pei; T. Yan | I36: IEEE Explore | P36: =IF(OR(N36="",O36=""),"",IF(N36=O36,"Igual","Diferente"))
A37: ES34 | D37: Research on Optimization Model of Cognitive Enhancement Algorithm in Intelligent Data Analysis System | E37: https://ieeexplore.ieee.org/stamp/stamp.jsp?arnumber=10835027 | F37: 2024 | G37: L. Tao; D. Xinyue; L. Yongjuan; L. Guangfu | I37: IEEE Explore | P37: =IF(OR(N37="",O37=""),"",IF(N37=O37,"Igual","Diferente"))
A38: ES35 | D38: The Role of Non-Invasive Neural Devices in Modern Neurorehabilitation and Mental Health Treatment | E38: https://ieeexplore.ieee.org/stamp/stamp.jsp?arnumber=11013597 | F38: 2025 | G38: A. Pawar; P. Gourshettiwar; P. M. Gote; V. K. Choudhary; P. Yesankar; S. Khadse | I38: IEEE Explore | P38: =IF(OR(N38="",O38=""),"",IF(N38=O38,"Igual","Diferente"))
A39: ES36 | D39: Real-Time Attention Regulation and Cognitive Monitoring Using a Wearable EEG-Based BCI | E39: https://ieeexplore.ieee.org/stamp/stamp.jsp?arnumber=10694718 | F39: 2025 | G39: H. Huang; J. Chen; J. Xiao; D. Chen; J. Zhang; J. Pan; Y. Li | I39: IEEE Explore | P39: =IF(OR(N39="",O39=""),"",IF(N39=O39,"Igual","Diferente"))
A40: ES37 | D40: Brain Wave Response of Style Geometry in Artistic Creation in VR Environments: an Impact Study on Cognitive Function and Mental Health of Autistic Children | E40: https://ieeexplore.ieee.org/stamp/stamp.jsp?arnumber=10686974 | F40: 2024 | G40: G. Peng; W. Y. Leong | I40: IEEE Explore | P40: =IF(OR(N40="",O40=""),"",IF(N40=O40,"Igual","Diferente"))
...

Sheet Cópia de Extração 1
A1: LLM1: CHATGPT
A2: LLM2: GEMINI
A3: ID do artigo | B3: Tipo de publicação | C3: Citação | D3: Local de publicação | E3: Título | F3: Link | G3: Ano | H3: Autores | I3: País | J3: Área de estudo | K3: Base de Dados | L3: RQ (Pergunta de Pesquisa) | M3: Extração LLM 1 (ChatGPT) | N3: Extração LLM 2 (Gemini) | O3: Extração validada (humana) | P3: ChatGPT acertou? | Q3: Gemini acertou? | R3: Concordância entre LLMs | S3: Observações / Comentários
A4: ES01 | B4: Journal | C4: Zhao X, Dang C, Maes JHR. Effects of working memory training on EEG, cognitive performance, and self-report indices potentially relevant for social anxiety. Biol Psychol. 2020 Feb;150:107840. doi: 10.1016/j.biopsycho.2019.107840. Epub 2020 Jan 2. PMID: 31904404. | D4: Biological Psychology | E4: Effects of working memory training on EEG, cognitive performance, and self-report indices potentially relevant for social anxiety | F4: PubMed | G4: 2020 | H4: Xin Zhao, Chen Dang, Joseph H R Maes | I4: China | J4: Psicologia Cognitiva | K4: PubMed | L4: RQ1 | M4: RQ1 — Excerpt: “No evidence found.” | Explanation: The article does not mention any Brain-Computer Interfaces (invasive, non-invasive, or hybrid). It focuses exclusively on working memory training and EEG as a measurement tool, not as a BCI. | N4: RQ1 — Excerpt: “No evidence found.” | Explanation: The article is a specific experimental study on Working Memory training using EEG/ERPs as measurement tools and does not review or categorize the types of Brain-Computer Interfaces (invasive, non-invasive, hybrid) most used in general mental health applications. | O4: Este artigo não trata diretamente de BCIs. Ele aborda treinamento de memória de trabalho (WM training) e medidas de EEG/ERP em estudantes com sintomas de ansiedade social. Portanto, não responde à RQ1. | P4: Sim | Q4: Sim | R4: =IF(OR(P4="",Q4=""),"",IF(P4=Q4,"Igual","Diferente")) -> Igual | S4: As respostas das duas LLMs apresentam alta concordância tanto no trecho citado quanto na explicação. Trecho citado (Excerpt): Ambas indicam “No evidence found.”, mostrando total acordo na conclusão sobre a ausência de informações relevantes no artigo quanto a BCIs. Explicação (Explanation): As duas LLMs apontam que o artigo foca em treinamento de memória de trabalho usando EEG como ferramenta de medida, e não em BCIs. A diferença está no detalhamento: a segunda (Gemini) menciona explicitamente ERPs e enfatiza que o artigo não revisa ou categoriza os tipos de BCIs em aplicações gerais de saúde mental.
I5: Netherlands | L5: RQ2 | M5: RQ2 — Excerpt: “No evidence found.” | Explanation: The study examines only social anxiety and does not reference other mental disorders in the context of BCI usage, nor does it discuss BCIs at all. | N5: RQ2 — Excerpt: “No evidence found.” | Explanation: The study focuses exclusively on Social Anxiety (SA) and does not provide a review or comparison of which mental disorders (such as depression, anxiety, schizophrenia, ADHD) have received the most attention in research involving BCIs. | O5: O artigo foca especificamente em ansiedade sociall. Trecho que destaca isso: “Social anxiety (SA) is quite common and associated with multiple comorbidities. Here, we examined the effects of working memory (WM) training on various indices potentially related to SA.” | P5: Sim | Q5: Sim | R5: =IF(OR(P5="",Q5=""),"",IF(P5=Q5,"Igual","Diferente")) -> Igual
L6: RQ3 | M6: RQ3 — Excerpt: “No evidence found.” | Explanation: The paper does not evaluate any BCI effectiveness. Its metrics concern cognitive tasks (WM, Stroop, dot-probe), EEG components (P1, N170, P2, N2), and self-report scales—not BCI outcomes. | N6: RQ3 — Excerpt: “Pre- and post-treatment assessments were made using questionnaires related to (social) anxiety and depression, and tasks measuring WM, interference control, and attentional biases towards, and event-related potentials (ERPs) elicited by, angry faces.” | Explanation: The evaluation methods used in this neuro-cognitive study include self-report measures (questionnaires), behavioral performance on cognitive tasks (WM, interference control), and electrophysiological signals (ERPs) recorded by EEG. | O6: Embora não seja um estudo de BCI, ele usa tals métricas de avaliação de treinamento cognitivo: Questionários: Liebowitz Social Anxiety Scale (LSAS), State-Trait Anxiety Inventory (STAI-T), Beck Depression Inventory (BDI-13). Tarefas cognitivas: Automated Operation Span Task (Aospan), Stroop Task, Dot-Probe Task. Medidas neurofisiológicas: ERP componentes P1, N170, P2, N2. | P6: Sim | Q6: Parcialmente | R6: =IF(OR(P6="",Q6=""),"",IF(P6=Q6,"Igual","Diferente")) -> Diferente | S6: O GPT teve a mesma percepção que a extração Humana
L7: RQ4 | M7: RQ4 — Excerpt: “working memory (WM) training… enhanced WM transfer task performance” | Explanation: Although the study is unrelated to BCIs, it does address cognitive enhancement—specifically improvements in working memory through behavioral training, not through BCI technology. | N7: RQ4 — Excerpt: “One treatment that, at least theoretically, could enhance the inﬂuence of the top-down system by strengthening EF is working memory (WM) training. WM, speciﬁcally WM updating, is an important component of executive functions... Accordingly, WM updating training might generally enhance attentional control and reduce...” | Explanation: The article explains that WM training, which strengthens Executive Function (EF), is a mechanism that can theoretically enhance cognitive abilities like attentional control, which in turn helps reduce anxiety symptoms. | O7: O artigo não usa BCI, mas mostra que treinamento de memória de trabalho pode melhorar atenção e reduzir sintomas de ansiedade, segundo tal trecho: “The training enhanced WM transfer task performance, reduced SA symptoms, and changed the amplitude of the P1, N170, P2, and N2 ERP components.” | P7: Sim | Q7: Parcialmente | R7: =IF(OR(P7="",Q7=""),"",IF(P7=Q7,"Igual","Diferente")) -> Diferente | S7: O GPT teve a mesma percepção que a extração Humana
L8: RQ5 | M8: RQ5 — Excerpt: “No evidence found.” | Explanation: The article does not discuss technical, clinical, or ethical barriers related to the use of BCIs in therapy or human enhancement. | N8: RQ5 — Excerpt: “No evidence found.” | Explanation: The article is an experimental report, not a systematic review, and therefore does not discuss or list the main technical, clinical, and ethical barriers that generally limit the adoption of BCI technology. | O8: O artigo não discute barreiras técnicas/éticas de BCI. | P8: Sim | Q8: Sim | R8: =IF(OR(P8="",Q8=""),"",IF(P8=Q8,"Igual","Diferente")) -> Igual
L9: RQ6 | M9: RQ6 — Excerpt: “No evidence found.” | Explanation: Nothing in the study addresses data security, privacy, or integrity of neural data in the context of BCIs. EEG is used only as a standard research measurement tool without discussion of neurodata ethics. | N9: RQ6 — Excerpt: “No evidence found.” | Explanation: The article is focused on the results of a training intervention for social anxiety and does not contain any discussion regarding the security, privacy, or integrity protocols for the neural data collected via EEG. | O9: Não há menção a segurança ou privacidade de dados neurais. | P9: Sim | Q9: Sim | R9: =IF(OR(P9="",Q9=""),"",IF(P9=Q9,"Igual","Diferente")) -> Igual
L10: RQ7 | M10: RQ7 — Excerpt: “No evidence found.” | Explanation: The paper does not mention emerging trends involving BCIs, AI integration, or personalized neurostimulation. | N10: RQ7 — Excerpt: “No evidence found.” | Explanation: The article is an original research paper detailing the results of an experiment and does not discuss or identify emerging trends regarding the future integration of BCIs with artificial intelligence or personalized neurostimulation. | O10: O artigo não aborda integração com IA ou neuroestimulação personalizada. | P10: Sim | Q10: Sim | R10: =IF(OR(P10="",Q10=""),"",IF(P10=Q10,"Igual","Diferente")) -> Igual
L11: RQ8 | M11: RQ8 — Excerpt: “No evidence found.” | Explanation: No ethical or philosophical reflections on “neurological expansion” or human capability amplification appear in the text. | N11: RQ8 — Excerpt: “No evidence found.” | Explanation: The article is a clinical study on anxiety treatment and does not engage with the broader ethical and philosophical aspects of "neurological expansion" or the general amplification of human capabilities. | O11: Não há discussão ética ou filosófica sobre expansão neurológica. | P11: Sim | Q11: Sim | R11: =IF(OR(P11="",Q11=""),"",IF(P11=Q11,"Igual","Diferente")) -> Igual
L12: RQ9 | M12: RQ9 — Excerpt: “No evidence found.” | Explanation: The article does not identify research gaps regarding BCIs; its discussion focuses only on working memory training, cognitive transfer, attentional bias, social anxiety, and EEG markers. | N12: RQ9 — Excerpt: “However, given methodological limitations, these results must be regarded as preliminary, and future research should further unravel the causal re-lation among the various indices of social anxiety and the eﬀect of WM training thereupon.” | Explanation: The key research gap identified in the conclusion is the need for future studies to fully determine and explain the causal relationship between the working memory training intervention and the observed changes in symptoms and neural indices of social anxiety. | O12: O artigo aponta lacunas sobre treinamento de memória e ansiedade social, mas não sobre o contexto BCIs: “These data provide preliminary evidence of the usefulness of WM trainings to reduce potential indices of SA, but further research is necessary to unravel the causal relation among these indices.” | P12: Sim | Q12: Não | R12: =IF(OR(P12="",Q12=""),"",IF(P12=Q12,"Igual","Diferente")) -> Diferente | S12: O gemini não considerou o contexto que deveria está ligado a BCIs
A13: ES02 | B13: Journal | C13: Kumar S, Zomorrodi R, Ghazala Z, Goodman MS, Blumberger DM, Daskalakis ZJ, Fischer CE, Mulsant BH, Pollock BG, Rajji TK. Effects of repetitive paired associative stimulation on brain plasticity and working memory in Alzheimer's disease: a pilot randomized double-blind-controlled trial. Int Psychogeriatr. 2023 Mar;35(3):143-155. doi: 10.1017/S1041610220003518. Epub 2020 Nov 16. PMID: 33190659. | D13: international psychogeriatrics | E13: Effects of repetitive paired associative stimulation on brain plasticity and working memory in Alzheimer's disease: a pilot randomized double-blind-controlled trial | F13: PubMed | G13: 2020 | H13: Sanjeev Kumar, Reza Zomorrodi, Zaid Ghazala, Michelle S Goodman, Daniel M Blumberger, Zafiris J Daskalakis, Corinne E Fischer, Benoit H Mulsant, Bruce G Pollock, Tarek K Rajji | I13: Canada | J13: Neurociência; Neurologia; Reabilitação Cognitiva | K13: PubMed | L13: RQ1 | M13: RQ1 — Excerpt: “No evidence found.” | Explanation: The article contains no references to Brain-Computer Interfaces (BCIs), whether invasive, non-invasive, or hybrid. | N13: RQ1 — Excerpt: “No evidence found.” | Explanation: The article is a specific clinical trial on repetitive paired associative stimulation (rPAS)/Transcranial Magnetic Stimulation (TMS) for Alzheimer's disease. It does not contain a general summary or comparative analysis of the most used types (invasive, non-invasive, hybrid) of Brain-Computer Interfaces across all mental health applications. | O13: Este estudo não utiliza diretamente BCIs clássicos, mas sim estimulação cerebral não invasiva: “Pilot randomized double-blind-controlled trial of repetitive paired associative stimulation (rPAS), a paradigm that combines transcranial magnetic stimulation (TMS) of the dorsolateral prefrontal cortex (DLPFC) with peripheral median nerve stimulation.” Isso se aproxima de BCI não-invasivo, pois envolve TMS + EEG para medir plasticidade e desempenho cognitivo mas não é de fato. | P13: Parcialmente | Q13: Parcialmente | R13: =IF(OR(P13="",Q13=""),"",IF(P13=Q13,"Igual","Diferente")) -> Igual | S13: Algumas coisas podem ser consideradas por se aproximarem de BCIs não invasivos
L14: RQ2 | M14: RQ2 — Excerpt: “No evidence found.” | Explanation: The paper does not discuss mental disorders in relation to BCIs. Any mental health content in the article is unrelated to brain–computer interfaces. | N14: RQ2 — Excerpt: “No evidence found.” | Explanation: The research article focuses specifically on Alzheimer's disease (AD) and its related cognitive deficits. It does not provide a comprehensive review or a list of which mental disorders (like depression, anxiety, or schizophrenia) have received the most attention in the broader field of BCI research. | O14: O artigo trata especificamente da doença de alzheimer, mas não em relação a BCIs. | P14: Sim | Q14: Sim | R14: =IF(OR(P14="",Q14=""),"",IF(P14=Q14,"Igual","Diferente")) -> Igual
L15: RQ3 | M15: RQ3 — Excerpt: “No evidence found.” | Explanation: The study does not evaluate BCI effectiveness, and therefore contains no metrics, evaluation methods, or outcomes related to BCIs. | N15: RQ3 — Excerpt: “DLPFC plasticity was assessed using single session PAS combined with electroencephalography (EEG) at baseline and on days 1, 7, and 14 post-rPAS. Working memory and theta-gamma coupling were assessed at the same time points using the N-back task and EEG.” | Explanation: In this study using a neurostimulation paradigm, the key metrics were DLPFC plasticity (measured by PAS-LTP via EEG), working memory performance (measured by the N-back task/A' score), and the corresponding theta-gamma coupling (measured by the Modulation Index via EEG). | O15: O artigo usa várias métricas, mas não relacionadas a BCIs: 1. Plasticidade cortical (PAS-LTP) medida por TMS-EEG. 2. Desempenho em memória de trabalho via N-back task. 3. Oscilações neurais: theta–gamma coupling. | P15: Parcialmente | Q15: Parcialmente | R15: =IF(OR(P15="",Q15=""),"",IF(P15=Q15,"Igual","Diferente")) -> Igual | S15: O GPT não destacou as metricas, mesmo que não relacionadas ao BCIs. O Gemini não destacou que as metricas não se relacionavam ao BCIs.
L16: RQ4 | M16: RQ4 — Excerpt: “No evidence found.” | Explanation: Although the article may involve cognitive or behavioral constructs, it does not describe the use of BCIs for enhancing memory, attention, or learning. | N16: RQ4 — Excerpt: “Thus, DLPFC plasticity could be an appropriate potential target and an intermediate marker for interventions aimed at enhancing work- ing memory in AD.” | Explanation: The article specifically addresses the use of rPAS (a TMS paradigm related to neurostimulation) as an intervention aimed at enhancing the cognitive ability of working memory by targeting DLPFC plasticity in patients with Alzheimer’s disease. | O16: O artigo mostra que o rPAS foi usado para tentar melhorar memória de trabalho em pacientes com Alzheimer. | P16: Sim | Q16: Parcialmente | R16: =IF(OR(P16="",Q16=""),"",IF(P16=Q16,"Igual","Diferente")) -> Diferente
L17: RQ5 | M17: RQ5 — Excerpt: “No evidence found.” | Explanation: There is no discussion of technical, clinical, or ethical barriers to the adoption of BCIs. | N17: RQ5 — Excerpt: “The top reason for failing screen was the travel and time commitment to the study, which raises the importance of adapting noninvasive brain stimulation to less mobile popula- tions such as AD.” | Explanation: While the article does not provide a comprehensive list of all technical, clinical, and ethical barriers in the field, it highlights a major logistical/clinical barrier in its own study: the high time commitment of the noninvasive brain stimulation protocol limited recruitment from less mobile patient populations | O17: O artigo não discute barreiras éticas ou técnicas de forma ampla. Ele apenas menciona limitações metodológicas. | P17: Sim | Q17: Parcialmente | R17: =IF(OR(P17="",Q17=""),"",IF(P17=Q17,"Igual","Diferente")) -> Diferente
L18: RQ6 | M18: RQ6 — Excerpt: “No evidence found.” | Explanation: The article does not address neural data security, privacy, or integrity in the context of BCIs. | N18: RQ6 — Excerpt: “No evidence found.” | Explanation: The article confirms that the study was approved by an Ethics Board and participants provided informed consent, but it does not contain any discussion, statement, or protocol details regarding the specific issues of security, privacy, or integrity of the collected neural (EEG) data. | O18: Não há menção a segurança ou privacidade dos dados neurais. | P18: Sim | Q18: Sim | R18: =IF(OR(P18="",Q18=""),"",IF(P18=Q18,"Igual","Diferente")) -> Igual
L19: RQ7 | M19: RQ7 — Excerpt: “No evidence found.” | Explanation: The paper does not mention emerging BCI trends, nor AI-BCI integration or personalized neurostimulation. | N19: RQ7 — Excerpt: “No evidence found.” | Explanation: The article focuses on future directions for the specific rPAS protocol (e.g., longer duration, alternative stimulation sites) but does not address emerging trends in the integration of BCIs with artificial intelligence or generalized personalized neurostimulation. | O19: O artigo não aborda IA ou neuroestimulação personalizada. | P19: Sim | Q19: Sim | R19: =IF(OR(P19="",Q19=""),"",IF(P19=Q19,"Igual","Diferente")) -> Igual
L20: RQ8 | M20: RQ8 — Excerpt: “No evidence found.” | Explanation: The article includes no ethical or philosophical discussion regarding neural enhancement or “neurological expansion.” | N20: RQ8 — Excerpt: “No evidence found.” | Explanation: The research is a clinical trial focused on a therapeutic intervention for a disease (Alzheimer's). It does not contain any philosophical or ethical commentary on the broader concepts of "neurological expansion" or the amplification of general human capabilities. | O20: Não há discussão ética ou filosófica sobre expansão neurológica. | P20: Sim | Q20: Sim | R20: =IF(OR(P20="",Q20=""),"",IF(P20=Q20,"Igual","Diferente")) -> Igual
L21: RQ9 | M21: RQ9 — Excerpt: “No evidence found.” | Explanation: The paper does not identify research gaps related to BCI applications in mental health or cognitive enhancement. | N21: RQ9 — Excerpt: “Future well-powered studies targeting such a population are needed, and if successful, additional studies should assess the effects of rPAS on other biological markers and behavioral symptoms of AD and as well as focus on overcoming barriers to implementation of rPAS for clinical use.” | Explanation: The primary research gaps highlighted are the need for larger, adequately powered studies, the need to assess effects on biological markers and behavioral symptoms, and the requirement to overcome implementation barriers for the neurostimulation technique to be translated into effective clinical care. | O21: O artigo aponta lacunas da abordagem de tratamento rPAS, mas não relacionadas ao BCIs ou coisas relacionadas. | P21: Sim | Q21: Não | R21: =IF(OR(P21="",Q21=""),"",IF(P21=Q21,"Igual","Diferente")) -> Diferente | S21: O gemini não levou em conta a necissade da relação com o tema de pesquisa da revisão sistematica.
A22: ES03 | B22: Journal | C22: Zhang K, Ji Y, Guo X, Gao T, Zhang X, Yu X, Wang J. The aperiodic and periodic activities of EEG dynamically relate with cognitive performance in schizophrenia. Schizophr Res Cogn. 2025 Jul 31;42:100383. doi: 10.1016/j.scog.2025.100383. PMID: 40792221; PMCID: PMC12337643. | D22: Schizophrenia Research: Cognition | E22: The aperiodic and periodic activities of EEG dynamically relate with cognitive performance in schizophrenia | F22: PubMed | G22: 2025 | H22: Kexin Zhang, Yunfei Ji, Xiaodong Guo, Tianqi Gao, Xuemin Zhang, Xin Yu, Jing Wang | I22: China | K22: PubMed | L22: RQ1 | M22: Excerpt: “No evidence found.” — Explanation: The article studies EEG aperiodic/periodic activity in schizophrenia and does not mention any Brain-Computer Interface (BCI) technology. | N22: No evidence found. The article describes the use of EEG, a non-invasive technique, in a research study on schizophrenia but does not provide a general review or comparison of the most used BCI types (invasive, non-invasive, hybrid) in mental health applications. | O22: Este estudo não usa diretamente BCIs, mas sim EEG (eletroencefalografia) para investigar atividade periódica e aperiódica em pacientes com esquizofrenia: “Before and after the language comprehension tasks (humor, metaphor and irony), the 5-min eyes-closed and eyes-open EEG signals were collected respectively.” | P22: Sim | Q22: Sim | R22: =IF(OR(P22="",Q22=""),"",IF(P22=Q22,"Igual","Diferente")) -> Igual
L23: RQ2 | M23: Excerpt: “No evidence found.” — Explanation: The study only involves schizophrenia and does not examine BCIs or their application to any mental disorders. | N23: No evidence found. The article focuses on schizophrenia (SCZ) and mentions related studies on chronic psychotic disorders and trait anxiety only in passing, but it does not review or state which mental disorder has received the most attention in BCI research. | O23: O artigo foca em esquizofrenia, mas não é relacionada ao uso de BCIs | P23: Sim | Q23: Sim | R23: =IF(OR(P23="",Q23=""),"",IF(P23=Q23,"Igual","Diferente")) -> Igual
L24: RQ3 | M24: Excerpt: “Power spectral density (PSD) helped to decompose EEG signals…”, “…aperiodic exponent and periodic power were extracted…”, and “Cognitive performance was assessed using the total Brief Assessment of Cognition in Schizophrenia (BACS).” main — Explanation: The study evaluates EEG effectiveness using PSD, aperiodic exponent, alpha/beta power, and correlates them with BACS cognitive test scores. These are EEG metrics, not BCI evaluation metrics. | N24: No evidence found. The paper describes metrics (BACS, Z scores) and methods (Pearson correlation, ANOVA) for assessing cognitive deficits in SCZ, but it does not discuss how to measure the effectiveness of BCIs in treatment. | O24: O estudo utiliza: EEG (aperiodic exponent, alpha e beta band power). Brief Assessment of Cognition in Schizophrenia (BACS). Tasks de compreensão de linguagem figurativa (humor, metáfora, ironia). | P24: Sim | Q24: Parcialmente | R24: =IF(OR(P24="",Q24=""),"",IF(P24=Q24,"Igual","Diferente")) -> Diferente
L25: RQ4 | M25: Excerpt: “The aperiodic exponent…showed significantly negative correlation with Z scores of humor comprehension tasks…” and “pre-tasks aperiodic exponent…positively correlated with T scores of attention and speed of information processing.” main — Explanation: The article links EEG spectral features to cognitive functions such as attention, processing speed, and language comprehension, but does not use BCIs for cognitive enhancement. | N25: No evidence found. The paper states that the aperiodic exponent relates to cognitive functions like "attention (Tagliazucchi et al., 2013), working memory (Kardan et al., 2020), motor performance (Immink et al., 2021) and academic learning (Cross et al., 2022)"1111, but it does not describe the use of BCIs for enhancing these abilities. | O25: O artigo mostra correlações entre EEG(não com BCIs) e desempenho cognitivo (atenção, velocidade de processamento, compreensão de humor/metáfora): “The pre-tasks aperiodic exponent in posterior location positively correlated with T scores of attention and speed of information processing.” | P25: Sim | Q25: Sim | R25: =IF(OR(P25="",Q25=""),"",IF(P25=Q25,"Igual","Diferente")) -> Igual
L26: RQ5 | M26: Excerpt: “No evidence found.” — Explanation: The paper does not discuss any technical, clinical, or ethical barriers to the adoption of BCIs. It only discusses EEG analysis limitations. | N26: No evidence found. The article discusses research limitations and heterogeneity in EEG studies but does not address the broader technical, clinical, and ethical barriers that limit the adoption of BCIs in therapeutic or human enhancement contexts. | O26: O artigo não discute barreiras éticas ou técnicas de BCI. | P26: Sim | Q26: Sim | R26: =IF(OR(P26="",Q26=""),"",IF(P26=Q26,"Igual","Diferente")) -> Igual
L27: RQ6 | M27: Excerpt: “No evidence found.” — Explanation: The study does not mention data security, privacy, or integrity concerns related to BCIs or neural data beyond basic ethical approval. | N27: No evidence found. The article mentions obtaining "written informed consent" 2 and ethical approval for the study, but it does not discuss technical or policy mechanisms regarding the security, privacy, or integrity of the collected neural data. | O27: Não há menção a segurança ou privacidade dos dados neurais. | P27: Sim | Q27: Sim | R27: =IF(OR(P27="",Q27=""),"",IF(P27=Q27,"Igual","Diferente")) -> Igual
L28: RQ7 | M28: Excerpt: “No evidence found.” — Explanation: The study does not discuss AI, neurostimulation, personalization, or future trends in BCI technology. | N28: Excerpt: "Finally, future research can be integrated with other modalities (e.g., fMRI, neurostimulation) to enhance spatial resolution or mechanistic insight." 3 — Explanation: The authors suggest that future research, including work on neurophysiological parameters like those studied, should be integrated with other modalities such as fMRI and neurostimulation to improve understanding. | O28: O artigo não aborda integração com IA ou neuroestimulação personalizada. | P28: Sim | Q28: Não | R28: =IF(OR(P28="",Q28=""),"",IF(P28=Q28,"Igual","Diferente")) -> Diferente
L29: RQ8 | M29: Excerpt: “No evidence found.” — Explanation: The article does not address ethical or philosophical issues related to neurological expansion or enhancement. | N29: No evidence found. The article is a research study on neurophysiology and schizophrenia and does not include a discussion of the ethical or philosophical implications of "neurological expansion" or the amplification of human capabilities. | O29: Não há discussão ética ou filosófica sobre expansão neurológica. | P29: Sim | Q29: Sim | R29: =IF(OR(P29="",Q29=""),"",IF(P29=Q29,"Igual","Diferente")) -> Igual
L30: RQ9 | M30: Excerpt: “Future studies should… integrate with other modalities (e.g., fMRI, neurostimulation) to enhance spatial resolution or mechanistic insight.” main — Explanation: The reported research gaps relate only to EEG-based cognition studies in schizophrenia, not BCIs; there is no mention of BCI applications. | N30: Excerpt: "Future experiments necessitate the development of validated scales or paradigms that have undergone rigorous reliability and validity testing." 4 — Explanation: The authors highlight the need for rigorously tested and validated scales and experimental paradigms as a key research gap to ensure the quality and reliability of future assessments in mental healthcare. | O30: O artigo aponta lacunas sobre a necessidade de investigar melhor a relação entre aperiodic exponent e desempenho cognitivo em esquizofrenia: “Our findings confirmed the higher aperiodic exponent with lower alpha and beta band in SCZ… The findings suggest that aperiodic exponent holds strong cognitive functional implications in SCZ.” | P30: Sim | Q30: Sim | R30: =IF(OR(P30="",Q30=""),"",IF(P30=Q30,"Igual","Diferente")) -> Igual
A31: ES04 | B31: Journal | C31: Enriquez-Geppert S, Krc J, O'Higgins FJ, Lietz M. Psilocybin-assisted neurofeedback for the improvement of executive functions: a randomized semi-naturalistic-lab feasibility study. Philos Trans R Soc Lond B Biol Sci. 2024 Dec 2;379(1915):20230095. doi: 10.1098/rstb.2023.0095. Epub 2024 Oct 21. PMID: 39428872; PMCID: PMC11513162. | D31: Philosophical Transactions of the Royal Society B | E31: Psilocybin-assisted neurofeedback for the improvement of executive functions: a randomized... feasibility study | F31: https://pubmed.ncbi.nlm.nih.gov/39428872/ | G31: 2024 | H31: Enriquez-Geppert S, et al. | I31: Netherlands | K31: PubMed | L31: RQ1 | M31: Excerpt: “No evidence found.” — Explanation: The article contains no discussion of Brain-Computer Interfaces (invasive, non-invasive, or hybrid) in any context. | N31: Excerpt: “Viviani & Velessi's [50] systematic review underscored that NF protocols targeting fm-theta are the most successful EEG protocols thus far regarding the improvement of EFs.” 1 Explanation: The article identifies frontal-midline theta neurofeedback (a non-invasive EEG method) as the most successful protocol for improving executive functions. | O31: Este estudo utiliza EEG neurofeedback (NF), que é uma forma de BCI não-invasiva. | P31: Não | Q31: Sim | R31: =IF(OR(P31="",Q31=""),"",IF(P31=Q31,"Igual","Diferente")) -> Diferente
L32: RQ2 | M32: Excerpt: “No evidence found.” — Explanation: The article does not mention any mental disorders (e.g., depression, anxiety, schizophrenia, ADHD) in relation to BCIs. | N32: No evidence found. Explanation: The article mentions that executive function deficits are "common in psychiatric disorders" 2 and references depression, stroke, and dementia in specific contexts, but it does not provide a general review ranking which disorders have received the most attention in BCI research. | O32: O artigo não foca em um transtorno específico, mas em déficits de funções executivas transdiagnósticos (presentes em várias condições psiquiátricas). | P32: Sim | Q32: Sim | R32: =IF(OR(P32="",Q32=""),"",IF(P32=Q32,"Igual","Diferente")) -> Igual
L33: RQ3 | M33: Excerpt: “No evidence found.” — Explanation: The text includes no metrics, evaluation methods, or outcome measures related to assessing BCI effectiveness. | N33: Excerpt: “Following three domains were assessed: (i) general placebo and expectancy (by general susceptibility and optimism, as well NF and psilocybin-assisted NF-specific experiences, attitudes and expectations), (ii) EFs (by self-rated EFs in daily life and four computerized experimental EF tasks), and (iii) functional abilities (by participant's priorities).” 3 Explanation: The authors evaluated effectiveness using a combination of placebo/expectancy questionnaires, objective computerized tasks, subjective daily life self-reports, and personalized functional goal ratings. | O33: O estudo usa: EEG frontal-midline theta power (indicador neural). Quatro tarefas de funções executivas: working memory updating, set-shifting, conflict monitoring, motor inhibition. Autoavaliações (BRIEF-A) sobre funções executivas na vida diária. Relatos de metas individuais de treinamento. | P33: Não | Q33: Sim | R33: =IF(OR(P33="",Q33=""),"",IF(P33=Q33,"Igual","Diferente")) -> Diferente
L34: RQ4 | M34: Excerpt: “No evidence found.” — Explanation: The paper does not discuss BCIs for enhancing memory, attention, learning, or other cognitive abilities. | N34: Excerpt: “Jackson et al. [42] observed a modest yet significant impact on episodic memory across both healthy and clinical groups... Significantly, fm-theta NF... has been identified as particularly effective in enhancing EFs in healthy individuals.” 4444 Explanation: The text cites previous studies showing that neurofeedback has been used to achieve significant improvements in episodic memory and executive functions (which include attention) in various populations. | O34: O artigo mostra que o neurofeedback assistido por psilocibina foi usado para melhorar funções executivas (memória de trabalho, atenção, inibição, monitoramento). | P34: Não | Q34: Sim | R34: =IF(OR(P34="",Q34=""),"",IF(P34=Q34,"Igual","Diferente")) -> Diferente
L35: RQ5 | M35: Excerpt: “No evidence found.” — Explanation: No technical, clinical, or ethical barriers to BCI adoption are mentioned or implied anywhere in the article. | N35: Excerpt: “Notably, inter-individual variability in learning to self-regulate brain activity, along with the presence of 'non-responders' [52,53], demands focused attention and solutions.” 5 Explanation: The authors identify the variability in learning success and the existence of "non-responders" (participants who fail to learn self-regulation) as primary clinical barriers to the adoption and efficacy of neurofeedback. | O35: O artigo menciona desafios como: Variabilidade individual (existência de “non-responders”). Necessidade de estudos maiores e controles ativos. Questões éticas do uso de psicodélicos (psilocibina) em conjunto com Neurofeedback | P35: Não | Q35: Sim | R35: =IF(OR(P35="",Q35=""),"",IF(P35=Q35,"Igual","Diferente")) -> Diferente
L36: RQ6 | M36: Excerpt: “No evidence found.” — Explanation: The article provides no coverage of security, privacy, or integrity of neural data. | N36: No evidence found. Explanation: While the article mentions obtaining informed consent 6and storing data on the OSF repository7, it does not discuss specific technical measures regarding the security, privacy, or integrity of the neural data. | O36: O artigo não discute segurança ou privacidade dos dados neurais. | P36: Sim | Q36: Sim | R36: =IF(OR(P36="",Q36=""),"",IF(P36=Q36,"Igual","Diferente")) -> Igual
L37: RQ7 | M37: Excerpt: “No evidence found.” — Explanation: The article contains no discussion of emerging BCI trends, AI integration, or personalized neurostimulation. | N37: Excerpt: “Recent advancements in NF methodology encompass real-time brain activity decoding [54], personalized NF tailored to individual anatomical and functional networks [55] and innovative NF techniques involving semantically guidance through mental states [56].” 8 Explanation: The article outlines emerging trends such as real-time decoding, personalization based on individual anatomy, and semantic guidance as key future directions for neurofeedback integration. | O37: O artigo menciona tendências como: Personalized NF(Neurofeedback Personalizado) adaptado a redes anatômicas e funcionais individuais. Uso de psicodélicos como potenciadores de neuroplasticidade em conjunto com Neurofeedback. | P37: Não | Q37: Sim | R37: =IF(OR(P37="",Q37=""),"",IF(P37=Q37,"Igual","Diferente")) -> Diferente
L38: RQ8 | M38: Excerpt: “No evidence found.” — Explanation: Ethical or philosophical issues related to neurological expansion or human capability amplification do not appear in the article. | N38: No evidence found. Explanation: The article focuses on the feasibility and efficacy of a specific clinical intervention (psilocybin-assisted neurofeedback) and does not address the broader ethical or philosophical implications of neurological expansion. | O38: O artigo toca em aspectos éticos do uso de psicodélicos para amplificação cognitiva, mas não discute profundamente filosofia da “expansão neurológica”. | P38: Sim | Q38: Sim | R38: =IF(OR(P38="",Q38=""),"",IF(P38=Q38,"Igual","Diferente")) -> Igual
L39: RQ9 | M39: Excerpt: “No evidence found.” — Explanation: The article does not address research gaps related to BCI technology, mental healthcare, or cognitive enhancement. | N39: Excerpt: “A thorough study with regular sessions and an active control group is crucial to evaluate EFs improvement and their specificity in future.” 9 Explanation: The authors conclude that to validate the method as an effective tool, future research must address current gaps by increasing the number of sessions and incorporating an active control group to rule out non-specific effects. | O39: O artigo aponta lacunas: Necessidade de estudos maiores e com grupo controle ativo. Avaliar especificidade dos ganhos em funções executivas. | P39: Não | Q39: Sim | R39: =IF(OR(P39="",Q39=""),"",IF(P39=Q39,"Igual","Diferente")) -> Diferente
A40: ES05 | B40: Journal | C40: Zemla K, Sedek G, Wróbel K, Postepski F, Wojcik GM. Investigating the Impact of Guided Imagery on Stress, Brain Functions, and Attention: A Randomized Trial. Sensors (Basel). 2023 Jul 7;23(13):6210. doi: 10.3390/s23136210. PMID: 37448060; PMCID: PMC10346678. | D40: Sensors (Basel) | E40: Investigating the Impact of Guided Imagery on Stress, Brain Functions, and Attention: A Randomized Trial | F40: https://pubmed.ncbi.nlm.nih.gov/37448060/ | G40: 2023 | H40: Zemla K, et al. | I40: Poland | K40: PubMed | L40: RQ1 | M40: No evidence Found | N40: No evidence Found | O40: Este estudo não usa diretamente BCIs clássicos, mas sim EEG para medir atividade cerebral durante guided imagery (GI). trata-se de um método não-invasivo (EEG). | P40: Não | Q40: Não | R40: =IF(OR(P40="",Q40=""),"",IF(P40=Q40,"Igual","Diferente")) -> Igual | S40: As LMMs não consideram EGG como metodo não invasivo.
...

Sheet Questões + Prompt
A1: PROMPT | B1: Task: Read the article and extract verbatim excerpts (exact text) that answer each Research Question (RQ). If the article does not answer an RQ, write: “No evidence found.” Also add a 1–2 sentence explanation for each answer. Return the final output as a table with two columns: | RQ | Response (Excerpt + Explanation) | Research Questions (do not modify): RQ1: What types of Brain-Computer Interfaces (invasive, non-invasive, hybrid) have been most used in mental health applications? RQ2: Which mental disorders have received the most attention in research involving BCIs (e.g., depression, anxiety, schizophrenia, ADHD)? RQ3: What metrics and evaluation methods are used to measure the effectiveness of BCIs in the treatment of mental disorders? RQ4: How have BCIs been used to enhance cognitive abilities such as memory, attention, and learning? RQ5: What are the main technical, clinical, and ethical barriers limiting the adoption of BCIs in therapeutic and human enhancement contexts? RQ6: How do current studies address issues of security, privacy, and integrity of neural data collected by BCIs? RQ7: What emerging trends point to the future of BCIs in integration with artificial intelligence and personalized neurostimulation? RQ8: How does the scientific literature address the ethical and philosophical aspects of "neurological expansion" and the amplification of human capabilities? RQ9: What research gaps still need to be explored for BCIs to become an effective and safe tool in mental healthcare and cognitive enhancement? Output Format (strict): Produce a table like this: RQ Response RQ1 Excerpt: “…” — Explanation: … RQ2 Excerpt: “…” — Explanation: … RQ3 Excerpt: “…” — Explanation: … RQ4 Excerpt: “…” — Explanation: … RQ5 Excerpt: “…” — Explanation: … RQ6 Excerpt: “…” — Explanation: … RQ7 Excerpt: “…” — Explanation: … RQ8 Excerpt: “…” — Explanation: … RQ9 Excerpt: “…” — Explanation: … Rules: – Use exact quoted text from the article (no paraphrasing). – Excerpt and Explanation must appear together in the same cell. – Choose the most relevant excerpt for each RQ. – If no answer exists, write “No evidence found.”
A2: RQ1: | B2: <<What types of Brain-Computer Interfaces (invasive, non-invasive, hybrid) have been most used in mental health applications?>> | C2: Quais tipos de Interfaces Cérebro-Computador (invasivas, não invasivas, híbridas) têm sido mais utilizadas em aplicações voltadas à saúde mental?
A3: RQ2: | B3: <<Which mental disorders have received the most attention in research involving BCIs (e.g., depression, anxiety, schizophrenia, ADHD)?>> | C3: Quais transtornos mentais têm recebido maior atenção nas pesquisas envolvendo BCIs (por exemplo, depressão, ansiedade, esquizofrenia, TDAH)?
A4: RQ3: | B4: <<What metrics and evaluation methods are used to measure the effectiveness of BCIs in the treatment of mental disorders?>> | C4: Quais métricas e métodos de avaliação são empregados para medir a eficácia das BCIs no tratamento de distúrbios mentais?
A5: RQ4: | B5: <<How have BCIs been used to enhance cognitive abilities such as memory, attention, and learning?>> | C5: De que forma as BCIs têm sido utilizadas para aprimorar capacidades cognitivas, como memória, atenção e aprendizado?
A6: RQ5: | B6: <<What are the main technical, clinical, and ethical barriers limiting the adoption of BCIs in therapeutic and human enhancement contexts?>> | C6: Quais são as principais barreiras técnicas, clínicas e éticas que limitam a adoção de BCIs em contextos terapêuticos e de amplificação humana?
A7: RQ6: | B7: <<How do current studies address issues of security, privacy, and integrity of neural data collected by BCIs?>> | C7: Como os estudos atuais abordam questões de segurança, privacidade e integridade dos dados neurais coletados por BCIs?
A8: RQ7: | B8: <<What emerging trends point to the future of BCIs in integration with artificial intelligence and personalized neurostimulation?>> | C8: Quais tendências emergentes apontam para o futuro das BCIs na integração com inteligência artificial e neuroestimulação personalizada?
A9: RQ8: | B9: <<How does the scientific literature address the ethical and philosophical aspects of "neurological expansion" and the amplification of human capabilities?>> | C9: Como a literatura científica trata os aspectos éticos e filosóficos da “expansão neurológica” e da amplificação das capacidades humanas?
A10: RQ9: | B10: <<What research gaps still need to be explored for BCIs to become an effective and safe tool in healthcare? mental e no aprimoramento cognitivo?>> | C10: Quais lacunas de pesquisa ainda precisam ser exploradas para que as BCIs se tornem uma ferramenta efetiva e segura na saúde mental e no aprimoramento cognitivo?

Sheet Extração
A1: ,sss
A2: LLM2: GEMINI
A3: ID do artigo | B3: Tipo de publicação | C3: Citação | D3: Local de publicação | E3: Título | F3: Link | G3: Ano | H3: Autores | I3: País | J3: Área de estudo | K3: Base de Dados | L3: RQ (Pergunta de Pesquisa) | M3: Extração LLM 1 (ChatGPT) | N3: Extração LLM 2 (Gemini) | O3: Extração validada (humana) | P3: ChatGPT acertou? | Q3: Gemini acertou? | R3: Concordância entre LLMs | S3: Observações / Comentários
A4: S1 | B4: Journal | C4: Zhao X, Dang C, Maes JHR. Effects of working memory training on EEG, cognitive performance, and self-report indices potentially relevant for social anxiety. Biol Psychol. 2020 Feb;150:107840. doi: 10.1016/j.biopsycho.2019.107840. Epub 2020 Jan 2. PMID: 31904404. | D4: Biological Psychology | E4: Effects of working memory training on EEG, cognitive performance, and self-report indices potentially relevant for social anxiety | F4: PubMed | G4: 2020 | H4: Xin Zhao, Chen Dang, Joseph H R Maes | I4: China | J4: Psicologia Cognitiva | K4: PubMed | L4: RQ1 | M4: RQ1 — Excerpt: “No evidence found.” | Explanation: The article does not mention any Brain-Computer Interfaces (invasive, non-invasive, or hybrid). It focuses exclusively on working memory training and EEG as a measurement tool, not as a BCI. | N4: RQ1 — Excerpt: “No evidence found.” | Explanation: The article is a specific experimental study on Working Memory training using EEG/ERPs as measurement tools and does not review or categorize the types of Brain-Computer Interfaces (invasive, non-invasive, hybrid) most used in general mental health applications. | O4: Este artigo não trata diretamente de BCIs. Ele aborda treinamento de memória de trabalho (WM training) e medidas de EEG/ERP em estudantes com sintomas de ansiedade social. Portanto, não responde à RQ1. | P4: Sim | Q4: Sim | R4: =IF(OR(P4="",Q4=""),"",IF(P4=Q4,"Igual","Diferente")) -> Igual | S4: As respostas das duas LLMs apresentam alta concordância tanto no trecho citado quanto na explicação. Trecho citado (Excerpt): Ambas indicam “No evidence found.”, mostrando total acordo na conclusão sobre a ausência de informações relevantes no artigo quanto a BCIs. Explicação (Explanation): As duas LLMs apontam que o artigo foca em treinamento de memória de trabalho usando EEG como ferramenta de medida, e não em BCIs. A diferença está no detalhamento: a segunda (Gemini) menciona explicitamente ERPs e enfatiza que o artigo não revisa ou categoriza os tipos de BCIs em aplicações gerais de saúde mental.
I5: Netherlands | L5: RQ2 | M5: RQ2 — Excerpt: “No evidence found.” | Explanation: The study examines only social anxiety and does not reference other mental disorders in the context of BCI usage, nor does it discuss BCIs at all. | N5: RQ2 — Excerpt: “No evidence found.” | Explanation: The study focuses exclusively on Social Anxiety (SA) and does not provide a review or comparison of which mental disorders (such as depression, anxiety, schizophrenia, ADHD) have received the most attention in research involving BCIs. | O5: O artigo foca especificamente em ansiedade sociall. Trecho que destaca isso: “Social anxiety (SA) is quite common and associated with multiple comorbidities. Here, we examined the effects of working memory (WM) training on various indices potentially related to SA.” | P5: Sim | Q5: Sim | R5: =IF(OR(P5="",Q5=""),"",IF(P5=Q5,"Igual","Diferente")) -> Igual
